input/example.txt
buy gtc 100 100
buy gtc 80 105
buy gtc 110 102
sell gtc 50 150
sell gtc 95 130
sell gtc 170 121
sell gtc 180 105.1

show book
show orders

cancel 4

show book
show orders

sell gtc 105 90

show book
show orders

buy ioc 200
sell ioc 90

show book
show orders

buy ioc 200 120
buy ioc 200 130
sell ioc 50 101

show book
show orders

buy fok 100
sell fok 80 125

show book
show orders

sell fok 40

show book
show orders
